<?xml version="1.0" ?>
<robot name="axis_q62" xmlns:xacro="http://wiki.ros.org/xacro">
  <!-- <xacro:macro name="axis_q62" params="prefix parent topic *origin"> -->
    <material name="black">
      <color rgba="0 0 0 1"/>
    </material>

    <link name="base_link"> 
    </link>
    
    <link name="axis_base_link">
      <inertial>
        <origin xyz="0 0 0" rpy="0 0 0" />
        <mass value="1" />
        <inertia
          ixx="1.0" ixy="0.0" ixz="0.0"
          iyy="1.0" iyz="0.0"
          izz="1.0" />
      </inertial>
    </link>
    <joint name="axis_base_joint" type="fixed">
      <!-- <xacro:insert_block name="origin" /> -->
      <origin rpy="0 0 0" xyz="-0.10 0 0.08"/>
      <parent link="base_link" />
      <child link="axis_base_link" />
    </joint>

    <link name="axis_body_link">
      <inertial>
        <origin xyz="0 0 0" rpy="0 0 0" />
        <mass value="1" />
        <inertia
          ixx="1.0" ixy="0.0" ixz="0.0"
          iyy="1.0" iyz="0.0"
          izz="1.0" />
      </inertial>
      <visual>
        <geometry>
          <mesh filename="package://axis_description/meshes/axis_q62_base.stl" scale="0.001 0.001 0.001" />
        </geometry>
        <material name="axis_grey">
          <color rgba="0.7 0.7 0.7 1.0" />
        </material>
        <origin xyz="-0.1 -0.17 0" rpy="0 0 0" />
      </visual>
      <collision>
        <geometry>
          <cylinder radius="0.085" length="0.22" />
        </geometry>
        <origin xyz="0 0 0.11" rpy="0 0 0" />
      </collision>
    </link>
    <joint name="axis_pan_joint" type="continuous">
      <axis xyz="0 0 -1" />
      <parent link="axis_base_link" />
      <child link="axis_body_link" />
      <origin xyz="0 0 0" rpy="0 0 0" />
    </joint>
    <gazebo reference="axis_body_link">
      <material>Gazebo/Grey</material>
    </gazebo>

    <link name="axis_head_link">
      <inertial>
        <origin xyz="0 0 0" rpy="0 0 0" />
        <mass value="1" />
        <inertia
          ixx="1.0" ixy="0.0" ixz="0.0"
          iyy="1.0" iyz="0.0"
          izz="1.0" />
      </inertial>
      <visual>
        <geometry>
          <mesh filename="package://axis_description/meshes/axis_q62_top.stl" scale="0.001 0.001 0.001" />
        </geometry>
        <material name="axis_grey">
          <color rgba="0.7 0.7 0.7 1.0" />
        </material>
        <origin xyz="-0.1 -0.165 -0.215" rpy="0 0 0" />
      </visual>
      <collision>
        <geometry>
          <cylinder radius="0.1" length="0.33" />
        </geometry>
        <origin xyz="0 0 0" rpy="1.5707963267948966 0 0" />
      </collision>
    </link>
    <joint name="axis_tilt_joint" type="revolute">
      <limit lower="-1.5707" upper="1.5707" effort="1" velocity="3.14159" />
      <axis xyz="0 -1 0" />
      <parent link="axis_body_link" />
      <child link="axis_head_link" />
      <origin xyz="0 0 0.215" rpy="0 0 0" />
    </joint>
    <gazebo reference="axis_head_link">
      <material>Gazebo/Grey</material>
    </gazebo>

    <!--
      Add the shades & gazebo reference frame
    -->
    <link name="axis_camera_link">
      <visual>
        <geometry>
          <box size="0.03 0.09 0.01" />
        </geometry>
        <origin xyz="-0.01 0 0.05" rpy="0 0 0" />
        <material name="black" />
      </visual>
      <visual>
        <geometry>
          <box size="0.03 0.09 0.01" />
        </geometry>
        <origin xyz="-0.01 0.20 0.05" rpy="0 0 0" />
        <material name="black" />
      </visual>
    </link>
    <joint name="axis_camera_joint" type="fixed">
      <parent link="axis_head_link" />
      <child link="axis_camera_link" />
      <origin xyz="0.1 -0.107 0" rpy="0 0 0" />
    </joint>

    <!--
      Simulation support: camera plugin & transmissions to allow control over the joints
    -->
    <transmission name="axis_pan_trans">
      <type>transmission_interface/SimpleTransmission</type>
      <joint name="axis_pan_joint">
        <hardwareInterface>hardware_interface/VelocityJointInterface</hardwareInterface>
      </joint>
      <actuator name="axis_pan_actuator">
          <mechanicalReduction>1</mechanicalReduction>
      </actuator>
    </transmission>
    <transmission name="axis_tilt_trans">
      <type>transmission_interface/SimpleTransmission</type>
      <joint name="axis_tilt_joint">
        <hardwareInterface>hardware_interface/VelocityJointInterface</hardwareInterface>
      </joint>
      <actuator name="axis_tilt_actuator">
          <mechanicalReduction>1</mechanicalReduction>
      </actuator>
    </transmission>
    <gazebo reference="axis_camera_link">
      <material>Gazebo/Black</material>
      <sensor type="camera" name="axis_ptz_camera">
        <update_rate>15</update_rate>
        <camera>
          <horizontal_fov>1.5184351666666667</horizontal_fov>
          <vertical_fov>1.0122901111111111</vertical_fov>
          <image>
            <width>640</width>
            <height>480</height>
            <format>R8G8B8</format>
          </image>
          <clip>
            <near>0.05</near>
            <far>500.0</far>
          </clip>
        </camera>
        <plugin name="axis_camera_controller" filename="libgazebo_ros_camera.so">
          <alwaysOn>true</alwaysOn>
          <cameraName>axis_camera</cameraName>
          <imageTopicName>image_raw</imageTopicName>
          <cameraInfoTopicName>camera_info</cameraInfoTopicName>
          <frameName>axis_camera_link</frameName>
        </plugin>
      </sensor>
    </gazebo>
  <!-- </xacro:macro> -->
</robot>